<sdf version='1.6'>
  <world name='default'>
    <model name='ground_plane'>
      <static>1</static>
      <link name='link'>
        <collision name='collision'>
          <geometry>
            <plane>
              <normal>0 0 1</normal>
              <size>100 100</size>
            </plane>
          </geometry>
          <surface>
            <friction>
              <ode>
                <mu>100</mu>
                <mu2>50</mu2>
              </ode>
              <torsional>
                <ode/>
              </torsional>
            </friction>
            <contact>
              <ode/>
            </contact>
            <bounce/>
          </surface>
          <max_contacts>10</max_contacts>
        </collision>
        <visual name='visual'>
          <cast_shadows>0</cast_shadows>
          <geometry>
            <plane>
              <normal>0 0 1</normal>
              <size>100 100</size>
            </plane>
          </geometry>
          <material>
            <script>
              <uri>file://media/materials/scripts/gazebo.material</uri>
              <name>Gazebo/Grey</name>
            </script>
          </material>
        </visual>
        <self_collide>0</self_collide>
        <kinematic>0</kinematic>
      </link>
    </model>
    <light name='sun' type='directional'>
      <cast_shadows>1</cast_shadows>
      <pose frame=''>0 0 10 0 -0 0</pose>
      <diffuse>0.8 0.8 0.8 1</diffuse>
      <specular>0.2 0.2 0.2 1</specular>
      <attenuation>
        <range>1000</range>
        <constant>0.9</constant>
        <linear>0.01</linear>
        <quadratic>0.001</quadratic>
      </attenuation>
      <direction>-0.5 0.1 -0.9</direction>
    </light>
    <physics name='default_physics' default='0' type='ode'>
      <real_time_update_rate>1000</real_time_update_rate>
      <max_step_size>0.001</max_step_size>
      <real_time_factor>1</real_time_factor>
    </physics>
    <gravity>0 0 -9.81</gravity>
    <gui fullscreen='0'>
      <camera name='user_camera'>
        <pose frame=''>2.27571 -0.038798 1.75717 0 0.612587 -3.13536</pose>
        <view_controller>orbit</view_controller>
        <projection_type>perspective</projection_type>
      </camera>
    </gui>
    <magnetic_field>6e-06 2.3e-05 -4.2e-05</magnetic_field>
    <atmosphere type='adiabatic'/>
    <scene>
      <ambient>0.4 0.4 0.4 1</ambient>
      <background>0.7 0.7 0.7 1</background>
      <shadows>1</shadows>
    </scene>
    <spherical_coordinates>
      <surface_model>EARTH_WGS84</surface_model>
      <latitude_deg>0</latitude_deg>
      <longitude_deg>0</longitude_deg>
      <elevation>0</elevation>
      <heading_deg>0</heading_deg>
    </spherical_coordinates>
    <model name='cafe_table'>
      <static>1</static>
      <link name='link'>
        <collision name='surface'>
          <pose frame=''>0 0 0.755 0 -0 0</pose>
          <geometry>
            <box>
              <size>0.913 0.913 0.04</size>
            </box>
          </geometry>
          <max_contacts>10</max_contacts>
          <surface>
            <contact>
              <ode/>
            </contact>
            <bounce/>
            <friction>
              <torsional>
                <ode/>
              </torsional>
              <ode/>
            </friction>
          </surface>
        </collision>
        <collision name='column'>
          <pose frame=''>0 0 0.37 0 -0 0</pose>
          <geometry>
            <box>
              <size>0.042 0.042 0.74</size>
            </box>
          </geometry>
          <max_contacts>10</max_contacts>
          <surface>
            <contact>
              <ode/>
            </contact>
            <bounce/>
            <friction>
              <torsional>
                <ode/>
              </torsional>
              <ode/>
            </friction>
          </surface>
        </collision>
        <collision name='base'>
          <pose frame=''>0 0 0.02 0 -0 0</pose>
          <geometry>
            <box>
              <size>0.56 0.56 0.04</size>
            </box>
          </geometry>
          <max_contacts>10</max_contacts>
          <surface>
            <contact>
              <ode/>
            </contact>
            <bounce/>
            <friction>
              <torsional>
                <ode/>
              </torsional>
              <ode/>
            </friction>
          </surface>
        </collision>
        <visual name='visual'>
          <geometry>
            <mesh>
              <uri>model://cafe_table/meshes/cafe_table.dae</uri>
            </mesh>
          </geometry>
        </visual>
        <self_collide>0</self_collide>
        <kinematic>0</kinematic>
      </link>
      <pose frame=''>0.75 0 0 0 -0 0</pose>
    </model>
    <model name='red_block'>
      <link name='red_block'>
        <pose frame=''>0 0 0 0 -0 0</pose>
        <inertial>
          <pose frame=''>0.025 0.025 0.025 0 -0 0</pose>
          <mass>0.5</mass>
          <inertia>
            <ixx>0.00016875</ixx>
            <ixy>0</ixy>
            <ixz>0</ixz>
            <iyy>0.00016875</iyy>
            <iyz>0</iyz>
            <izz>0.00016875</izz>
          </inertia>
        </inertial>
        <collision name='red_block_collision'>
          <pose frame=''>0.025 0.025 0.025 0 -0 0</pose>
          <geometry>
            <box>
              <size>0.045 0.045 0.045</size>
            </box>
          </geometry>
          <surface>
            <contact>
              <ode/>
            </contact>
            <friction>
              <ode>
                <mu>1000</mu>
                <mu2>1000</mu2>
              </ode>
              <torsional>
                <ode/>
              </torsional>
            </friction>
            <bounce/>
          </surface>
          <max_contacts>10</max_contacts>
        </collision>
        <visual name='red_block_visual'>
          <pose frame=''>0.025 0.025 0.025 0 -0 0</pose>
          <geometry>
            <box>
              <size>0.045 0.045 0.045</size>
            </box>
          </geometry>
          <material>
            <script>
              <name>Gazebo/Red</name>
              <uri>file://media/materials/scripts/gazebo.material</uri>
            </script>
          </material>
        </visual>
        <gravity>1</gravity>
        <velocity_decay/>
        <self_collide>0</self_collide>
        <kinematic>0</kinematic>
      </link>
      <pose frame=''>0.4225 0.1265 0.7725 0 -0 0</pose>
    </model>
    <model name='sawyer'>
      <link name='base'>
        <pose frame=''>0 0 0 0 -0 0</pose>
        <inertial>
          <pose frame=''>-2.1e-05 -1e-06 -0.481108 0 -0 0</pose>
          <mass>62.9727</mass>
          <inertia>
            <ixx>5.7592</ixx>
            <ixy>0.000992111</ixy>
            <ixz>0.802701</ixz>
            <iyy>6.78253</iyy>
            <iyz>0.00110068</iyz>
            <izz>5.00932</izz>
          </inertia>
        </inertial>
        <collision name='base_fixed_joint_lump__controller_box_collision'>
          <pose frame=''>-0.325 0 -0.38 0 -0 0</pose>
          <geometry>
            <box>
              <size>0.22 0.4 0.53</size>
            </box>
          </geometry>
          <max_contacts>10</max_contacts>
          <surface>
            <contact>
              <ode/>
            </contact>
            <bounce/>
            <friction>
              <torsional>
                <ode/>
              </torsional>
              <ode/>
            </friction>
          </surface>
        </collision>
        <collision name='base_fixed_joint_lump__pedestal_feet_collision_1'>
          <pose frame=''>-0.1225 0 -0.758 0 -0 0</pose>
          <geometry>
            <box>
              <size>0.77 0.7 0.31</size>
            </box>
          </geometry>
          <max_contacts>10</max_contacts>
          <surface>
            <contact>
              <ode/>
            </contact>
            <bounce/>
            <friction>
              <torsional>
                <ode/>
              </torsional>
              <ode/>
            </friction>
          </surface>
        </collision>
        <collision name='base_fixed_joint_lump__pedestal_collision_2'>
          <pose frame=''>-0.02 0 -0.29 0 -0 0</pose>
          <geometry>
            <cylinder>
              <length>0.62</length>
              <radius>0.18</radius>
            </cylinder>
          </geometry>
          <surface>
            <contact>
              <ode/>
            </contact>
            <friction>
              <ode/>
              <torsional>
                <ode/>
              </torsional>
            </friction>
            <bounce/>
          </surface>
          <max_contacts>10</max_contacts>
        </collision>
        <collision name='base_fixed_joint_lump__right_arm_base_link_collision_3'>
          <pose frame=''>0 0 0.12 0 -0 0</pose>
          <geometry>
            <cylinder>
              <length>0.24</length>
              <radius>0.08</radius>
            </cylinder>
          </geometry>
          <max_contacts>10</max_contacts>
          <surface>
            <contact>
              <ode/>
            </contact>
            <bounce/>
            <friction>
              <torsional>
                <ode/>
              </torsional>
              <ode/>
            </friction>
          </surface>
        </collision>
        <visual name='base_fixed_joint_lump__pedestal_visual'>
          <pose frame=''>0.26 0.345 -0.91488 1.5708 0 -1.5708</pose>
          <geometry>
            <mesh>
              <scale>1 1 1</scale>
              <uri>/home/carl/CUBoulder/robotics/workspaces/sawyer_ws/src/sawyer_robot/sawyer_description/meshes/sawyer_pv/pedestal.DAE</uri>
            </mesh>
          </geometry>
          <material>
            <script>
              <name>Gazebo/FlatBlack</name>
              <uri>file://media/materials/scripts/gazebo.material</uri>
            </script>
          </material>
        </visual>
        <visual name='base_fixed_joint_lump__right_arm_base_link_visual_1'>
          <pose frame=''>0 0 0 0 -0 0</pose>
          <geometry>
            <mesh>
              <scale>1 1 1</scale>
              <uri>/home/carl/CUBoulder/robotics/workspaces/sawyer_ws/src/sawyer_robot/sawyer_description/meshes/sawyer_pv/base.DAE</uri>
            </mesh>
          </geometry>
        </visual>
        <visual name='base_fixed_joint_lump__torso_visual_2'>
          <pose frame=''>0 0 0 0 -0 0</pose>
          <geometry>
            <box>
              <size>0.001 0.001 0.001</size>
            </box>
          </geometry>
          <material>
            <script>
              <uri>__default__</uri>
              <name>__default__</name>
            </script>
          </material>
        </visual>
        <velocity_decay/>
        <gravity>1</gravity>
        <velocity_decay/>
        <self_collide>1</self_collide>
        <kinematic>0</kinematic>
      </link>
      <joint name='fixed' type='fixed'>
        <child>base</child>
        <parent>world</parent>
      </joint>
      <link name='right_l0'>
        <pose frame=''>0 0 0.08 0 -0 0</pose>
        <inertial>
          <pose frame=''>0.024217 0.010948 0.143773 0 -0 0</pose>
          <mass>5.3313</mass>
          <inertia>
            <ixx>0.0633734</ixx>
            <ixy>0.00470061</ixy>
            <ixz>0.0117945</ixz>
            <iyy>0.0680231</iyy>
            <iyz>0.00802626</iyz>
            <izz>0.0337231</izz>
          </inertia>
        </inertial>
        <collision name='right_l0_collision'>
          <pose frame=''>0.08 0 0.23 0 -0 0</pose>
          <geometry>
            <sphere>
              <radius>0.07</radius>
            </sphere>
          </geometry>
          <max_contacts>10</max_contacts>
          <surface>
            <contact>
              <ode/>
            </contact>
            <bounce/>
            <friction>
              <torsional>
                <ode/>
              </torsional>
              <ode/>
            </friction>
          </surface>
        </collision>
        <visual name='right_l0_visual'>
          <pose frame=''>0 0 0 0 -0 0</pose>
          <geometry>
            <mesh>
              <scale>1 1 1</scale>
              <uri>/home/carl/CUBoulder/robotics/workspaces/sawyer_ws/src/sawyer_robot/sawyer_description/meshes/sawyer_mp3/l0.DAE</uri>
            </mesh>
          </geometry>
        </visual>
        <self_collide>0</self_collide>
        <kinematic>0</kinematic>
      </link>
      <joint name='right_j0' type='revolute'>
        <child>right_l0</child>
        <parent>base</parent>
        <axis>
          <xyz>0 0 1</xyz>
          <limit>
            <lower>-3.0503</lower>
            <upper>3.0503</upper>
            <effort>80</effort>
            <velocity>1.74</velocity>
          </limit>
          <dynamics>
            <damping>15</damping>
            <friction>5</friction>
            <spring_reference>0</spring_reference>
            <spring_stiffness>0</spring_stiffness>
          </dynamics>
          <use_parent_model_frame>1</use_parent_model_frame>
        </axis>
        <physics>
          <provide_feedback>1</provide_feedback>
          <ode>
            <provide_feedback>1</provide_feedback>
            <implicit_spring_damper>1</implicit_spring_damper>
            <cfm_damping>1</cfm_damping>
            <limit>
              <cfm>0</cfm>
              <erp>0.2</erp>
            </limit>
          </ode>
        </physics>
      </joint>
      <link name='head'>
        <pose frame=''>0 0 0.3765 0 -0 0</pose>
        <inertial>
          <pose frame=''>0.005584 -2.6e-05 0.102834 0 -0 0</pose>
          <mass>1.5995</mass>
          <inertia>
            <ixx>0.0319633</ixx>
            <ixy>-4.47795e-06</ixy>
            <ixz>2.90067e-05</ixz>
            <iyy>0.0284102</iyy>
            <iyz>3.90469e-07</iyz>
            <izz>0.0249751</izz>
          </inertia>
        </inertial>
        <collision name='head_collision'>
          <pose frame=''>0 0 0.08 0 -0 0</pose>
          <geometry>
            <sphere>
              <radius>0.18</radius>
            </sphere>
          </geometry>
          <max_contacts>10</max_contacts>
          <surface>
            <contact>
              <ode/>
            </contact>
            <bounce/>
            <friction>
              <torsional>
                <ode/>
              </torsional>
              <ode/>
            </friction>
          </surface>
        </collision>
        <collision name='head_fixed_joint_lump__screen_collision_1'>
          <pose frame=''>0.03 0 0.105 1.5708 -0 1.5708</pose>
          <geometry>
            <sphere>
              <radius>0.001</radius>
            </sphere>
          </geometry>
          <surface>
            <contact>
              <ode/>
            </contact>
            <friction>
              <ode/>
              <torsional>
                <ode/>
              </torsional>
            </friction>
            <bounce/>
          </surface>
          <max_contacts>10</max_contacts>
        </collision>
        <visual name='head_visual'>
          <pose frame=''>0 0 0 0 -0 0</pose>
          <geometry>
            <mesh>
              <scale>1 1 1</scale>
              <uri>/home/carl/CUBoulder/robotics/workspaces/sawyer_ws/src/sawyer_robot/sawyer_description/meshes/sawyer_pv/head.DAE</uri>
            </mesh>
          </geometry>
        </visual>
        <visual name='head_fixed_joint_lump__screen_visual_1'>
          <pose frame=''>0.03 0 0.105 1.5708 -0 1.5708</pose>
          <geometry>
            <box>
              <size>0.24 0.14 0.002</size>
            </box>
          </geometry>
          <plugin name='screen_video_controller' filename='libgazebo_ros_video.so'>
            <height>600</height>
            <width>1024</width>
            <topicName>/robot/head_display</topicName>
            <robotNamespace>/robot</robotNamespace>
          </plugin>
          <material>
            <script>
              <uri>__default__</uri>
              <name>__default__</name>
            </script>
          </material>
        </visual>
        <velocity_decay/>
        <gravity>1</gravity>
        <velocity_decay/>
        <sensor name='head_camera' type='camera'>
          <update_rate>10</update_rate>
          <camera name='head_camera'>
            <horizontal_fov>2.00787</horizontal_fov>
            <image>
              <width>1280</width>
              <height>800</height>
              <format>R8G8B8</format>
            </image>
            <clip>
              <near>0.1</near>
              <far>50</far>
            </clip>
          </camera>
          <plugin name='camera_controller' filename='libgazebo_ros_camera.so'>
            <alwaysOn>true</alwaysOn>
            <updateRate>10</updateRate>
            <cameraName>head_camera</cameraName>
            <imageTopicName>/io/internal_camera/head_camera/image_raw</imageTopicName>
            <cameraInfoTopicName>/io/internal_camera/head_camera/camera_info</cameraInfoTopicName>
            <frameName>head_camera</frameName>
            <focalLength>407.391526</focalLength>
            <robotNamespace>/</robotNamespace>
          </plugin>
          <pose frame=''>0.022803 0 0.216572 0 0.558504 0</pose>
        </sensor>
        <self_collide>0</self_collide>
        <kinematic>0</kinematic>
      </link>
      <joint name='head_pan' type='revolute'>
        <child>head</child>
        <parent>right_l0</parent>
        <axis>
          <xyz>0 0 1</xyz>
          <limit>
            <lower>-5.0952</lower>
            <upper>0.9064</upper>
            <effort>8</effort>
            <velocity>1.8</velocity>
          </limit>
          <dynamics>
            <damping>1</damping>
            <friction>0.5</friction>
            <spring_reference>0</spring_reference>
            <spring_stiffness>0</spring_stiffness>
          </dynamics>
          <use_parent_model_frame>1</use_parent_model_frame>
        </axis>
        <physics>
          <provide_feedback>1</provide_feedback>
          <ode>
            <provide_feedback>1</provide_feedback>
            <implicit_spring_damper>1</implicit_spring_damper>
            <cfm_damping>1</cfm_damping>
            <limit>
              <cfm>0</cfm>
              <erp>0.2</erp>
            </limit>
          </ode>
        </physics>
      </joint>
      <link name='right_l1'>
        <pose frame=''>0.081 0.05 0.317 1.57079 1.57079 3.14159</pose>
        <inertial>
          <pose frame=''>-0.003078 -0.026752 0.092316 0 -0 0</pose>
          <mass>4.515</mass>
          <inertia>
            <ixx>0.0324906</ixx>
            <ixy>-0.000240685</ixy>
            <ixz>-0.000290772</ixz>
            <iyy>0.0246985</iyy>
            <iyz>-0.00606275</iyz>
            <izz>0.0273023</izz>
          </inertia>
        </inertial>
        <collision name='right_l1_collision'>
          <pose frame=''>0 0 0.1225 0 -0 0</pose>
          <geometry>
            <sphere>
              <radius>0.07</radius>
            </sphere>
          </geometry>
          <max_contacts>10</max_contacts>
          <surface>
            <contact>
              <ode/>
            </contact>
            <bounce/>
            <friction>
              <torsional>
                <ode/>
              </torsional>
              <ode/>
            </friction>
          </surface>
        </collision>
        <collision name='right_l1_2_collision_1'>
          <pose frame=''>0 0 0.035 0 -0 0</pose>
          <geometry>
            <cylinder>
              <length>0.14</length>
              <radius>0.07</radius>
            </cylinder>
          </geometry>
          <max_contacts>10</max_contacts>
          <surface>
            <contact>
              <ode/>
            </contact>
            <bounce/>
            <friction>
              <torsional>
                <ode/>
              </torsional>
              <ode/>
            </friction>
          </surface>
        </collision>
        <visual name='right_l1_visual'>
          <pose frame=''>0 0 0 0 -0 0</pose>
          <geometry>
            <mesh>
              <scale>1 1 1</scale>
              <uri>/home/carl/CUBoulder/robotics/workspaces/sawyer_ws/src/sawyer_robot/sawyer_description/meshes/sawyer_mp3/l1.DAE</uri>
            </mesh>
          </geometry>
        </visual>
        <self_collide>0</self_collide>
        <kinematic>0</kinematic>
      </link>
      <joint name='right_j1' type='revolute'>
        <child>right_l1</child>
        <parent>right_l0</parent>
        <axis>
          <xyz>0 1 0</xyz>
          <limit>
            <lower>-3.8095</lower>
            <upper>2.2736</upper>
            <effort>80</effort>
            <velocity>1.328</velocity>
          </limit>
          <dynamics>
            <damping>5</damping>
            <friction>2</friction>
            <spring_reference>0</spring_reference>
            <spring_stiffness>0</spring_stiffness>
          </dynamics>
          <use_parent_model_frame>1</use_parent_model_frame>
        </axis>
        <physics>
          <provide_feedback>1</provide_feedback>
          <ode>
            <provide_feedback>1</provide_feedback>
            <implicit_spring_damper>1</implicit_spring_damper>
            <cfm_damping>1</cfm_damping>
            <limit>
              <cfm>0</cfm>
              <erp>0.2</erp>
            </limit>
          </ode>
        </physics>
      </joint>
      <link name='right_l2'>
        <pose frame=''>0.221 0.1925 0.317 3.14159 1.57079 3.14159</pose>
        <inertial>
          <pose frame=''>-0.00016 -0.014882 0.135046 0 -0 0</pose>
          <mass>1.755</mass>
          <inertia>
            <ixx>0.0356916</ixx>
            <ixy>4.38622e-06</ixy>
            <ixz>1.51717e-05</ixz>
            <iyy>0.0354834</iyy>
            <iyz>-0.00330019</iyz>
            <izz>0.0134201</izz>
          </inertia>
        </inertial>
        <collision name='right_l2_collision'>
          <pose frame=''>0 0 0.08 0 -0 0</pose>
          <geometry>
            <cylinder>
              <length>0.34</length>
              <radius>0.06</radius>
            </cylinder>
          </geometry>
          <max_contacts>10</max_contacts>
          <surface>
            <contact>
              <ode/>
            </contact>
            <bounce/>
            <friction>
              <torsional>
                <ode/>
              </torsional>
              <ode/>
            </friction>
          </surface>
        </collision>
        <collision name='right_l2_2_collision_1'>
          <pose frame=''>0 0 0.26 0 -0 0</pose>
          <geometry>
            <sphere>
              <radius>0.06</radius>
            </sphere>
          </geometry>
          <max_contacts>10</max_contacts>
          <surface>
            <contact>
              <ode/>
            </contact>
            <bounce/>
            <friction>
              <torsional>
                <ode/>
              </torsional>
              <ode/>
            </friction>
          </surface>
        </collision>
        <visual name='right_l2_visual'>
          <pose frame=''>0 0 0 0 -0 0</pose>
          <geometry>
            <mesh>
              <scale>1 1 1</scale>
              <uri>/home/carl/CUBoulder/robotics/workspaces/sawyer_ws/src/sawyer_robot/sawyer_description/meshes/sawyer_pv/l2.DAE</uri>
            </mesh>
          </geometry>
        </visual>
        <self_collide>0</self_collide>
        <kinematic>0</kinematic>
      </link>
      <joint name='right_j2' type='revolute'>
        <child>right_l2</child>
        <parent>right_l1</parent>
        <axis>
          <xyz>1 0 0</xyz>
          <limit>
            <lower>-3.0426</lower>
            <upper>3.0426</upper>
            <effort>40</effort>
            <velocity>1.957</velocity>
          </limit>
          <dynamics>
            <damping>5</damping>
            <friction>2</friction>
            <spring_reference>0</spring_reference>
            <spring_stiffness>0</spring_stiffness>
          </dynamics>
          <use_parent_model_frame>1</use_parent_model_frame>
        </axis>
        <physics>
          <provide_feedback>1</provide_feedback>
          <ode>
            <provide_feedback>1</provide_feedback>
            <implicit_spring_damper>1</implicit_spring_damper>
            <cfm_damping>1</cfm_damping>
            <limit>
              <cfm>0</cfm>
              <erp>0.2</erp>
            </limit>
          </ode>
        </physics>
      </joint>
      <link name='right_l3'>
        <pose frame=''>0.481 0.1505 0.317 1.57079 1.57079 3.14159</pose>
        <inertial>
          <pose frame=''>-0.004814 -0.0281 -0.084154 0 -0 0</pose>
          <mass>2.5097</mass>
          <inertia>
            <ixx>0.01016</ixx>
            <ixy>-9.7452e-06</ixy>
            <ixz>0.00026624</ixz>
            <iyy>0.0065685</iyy>
            <iyz>0.0030316</iyz>
            <izz>0.0069078</izz>
          </inertia>
        </inertial>
        <collision name='right_l3_collision'>
          <pose frame=''>0 -0.01 -0.12 0 -0 0</pose>
          <geometry>
            <sphere>
              <radius>0.06</radius>
            </sphere>
          </geometry>
          <max_contacts>10</max_contacts>
          <surface>
            <contact>
              <ode/>
            </contact>
            <bounce/>
            <friction>
              <torsional>
                <ode/>
              </torsional>
              <ode/>
            </friction>
          </surface>
        </collision>
        <visual name='right_l3_visual'>
          <pose frame=''>0 0 0 0 -0 0</pose>
          <geometry>
            <mesh>
              <scale>1 1 1</scale>
              <uri>/home/carl/CUBoulder/robotics/workspaces/sawyer_ws/src/sawyer_robot/sawyer_description/meshes/sawyer_pv/l3.DAE</uri>
            </mesh>
          </geometry>
        </visual>
        <self_collide>0</self_collide>
        <kinematic>0</kinematic>
      </link>
      <joint name='right_j3' type='revolute'>
        <child>right_l3</child>
        <parent>right_l2</parent>
        <axis>
          <xyz>0 1 0</xyz>
          <limit>
            <lower>-3.0439</lower>
            <upper>3.0439</upper>
            <effort>40</effort>
            <velocity>1.957</velocity>
          </limit>
          <dynamics>
            <damping>15</damping>
            <friction>5</friction>
            <spring_reference>0</spring_reference>
            <spring_stiffness>0</spring_stiffness>
          </dynamics>
          <use_parent_model_frame>1</use_parent_model_frame>
        </axis>
        <physics>
          <provide_feedback>1</provide_feedback>
          <ode>
            <provide_feedback>1</provide_feedback>
            <implicit_spring_damper>1</implicit_spring_damper>
            <cfm_damping>1</cfm_damping>
            <limit>
              <cfm>0</cfm>
              <erp>0.2</erp>
            </limit>
          </ode>
        </physics>
      </joint>
      <link name='right_l4'>
        <pose frame=''>0.606 0.024 0.317 3.14159 1.57079 3.14159</pose>
        <inertial>
          <pose frame=''>-0.002336 0.006778 0.132396 0 -0 0</pose>
          <mass>1.1336</mass>
          <inertia>
            <ixx>0.0337694</ixx>
            <ixy>1.46364e-05</ixy>
            <ixz>0.000107239</ixz>
            <iyy>0.0337945</iyy>
            <iyz>0.001043</iyz>
            <izz>0.0213948</izz>
          </inertia>
        </inertial>
        <collision name='right_l4_collision'>
          <pose frame=''>0 0 0.11 0 -0 0</pose>
          <geometry>
            <cylinder>
              <length>0.3</length>
              <radius>0.045</radius>
            </cylinder>
          </geometry>
          <max_contacts>10</max_contacts>
          <surface>
            <contact>
              <ode/>
            </contact>
            <bounce/>
            <friction>
              <torsional>
                <ode/>
              </torsional>
              <ode/>
            </friction>
          </surface>
        </collision>
        <collision name='right_l4_2_collision_1'>
          <pose frame=''>0 0.01 0.26 0 -0 0</pose>
          <geometry>
            <sphere>
              <radius>0.06</radius>
            </sphere>
          </geometry>
          <max_contacts>10</max_contacts>
          <surface>
            <contact>
              <ode/>
            </contact>
            <bounce/>
            <friction>
              <torsional>
                <ode/>
              </torsional>
              <ode/>
            </friction>
          </surface>
        </collision>
        <visual name='right_l4_visual'>
          <pose frame=''>0 0 0 0 -0 0</pose>
          <geometry>
            <mesh>
              <scale>1 1 1</scale>
              <uri>/home/carl/CUBoulder/robotics/workspaces/sawyer_ws/src/sawyer_robot/sawyer_description/meshes/sawyer_pv/l4.DAE</uri>
            </mesh>
          </geometry>
        </visual>
        <self_collide>0</self_collide>
        <kinematic>0</kinematic>
      </link>
      <joint name='right_j4' type='revolute'>
        <child>right_l4</child>
        <parent>right_l3</parent>
        <axis>
          <xyz>1 0 0</xyz>
          <limit>
            <lower>-2.9761</lower>
            <upper>2.9761</upper>
            <effort>9</effort>
            <velocity>3.485</velocity>
          </limit>
          <dynamics>
            <damping>6</damping>
            <friction>1</friction>
            <spring_reference>0</spring_reference>
            <spring_stiffness>0</spring_stiffness>
          </dynamics>
          <use_parent_model_frame>1</use_parent_model_frame>
        </axis>
        <physics>
          <provide_feedback>1</provide_feedback>
          <ode>
            <provide_feedback>1</provide_feedback>
            <implicit_spring_damper>1</implicit_spring_damper>
            <cfm_damping>1</cfm_damping>
            <limit>
              <cfm>0</cfm>
              <erp>0.2</erp>
            </limit>
          </ode>
        </physics>
      </joint>
      <link name='right_l5'>
        <pose frame=''>0.881 0.055 0.317 1.57079 1.57079 3.14159</pose>
        <inertial>
          <pose frame=''>0.006286 -0.023606 0.076556 0 -0 0</pose>
          <mass>1.5825</mass>
          <inertia>
            <ixx>0.0247481</ixx>
            <ixy>0.000119844</ixy>
            <ixz>5.03922e-05</ixz>
            <iyy>0.022988</iyy>
            <iyz>-0.00116319</iyz>
            <izz>0.0231942</izz>
          </inertia>
        </inertial>
        <collision name='right_l5_collision'>
          <pose frame=''>0 0 0.1 0 -0 0</pose>
          <geometry>
            <sphere>
              <radius>0.06</radius>
            </sphere>
          </geometry>
          <max_contacts>10</max_contacts>
          <surface>
            <contact>
              <ode/>
            </contact>
            <bounce/>
            <friction>
              <torsional>
                <ode/>
              </torsional>
              <ode/>
            </friction>
          </surface>
        </collision>
        <visual name='right_l5_visual'>
          <pose frame=''>0 0 0 0 -0 0</pose>
          <geometry>
            <mesh>
              <scale>1 1 1</scale>
              <uri>/home/carl/CUBoulder/robotics/workspaces/sawyer_ws/src/sawyer_robot/sawyer_description/meshes/sawyer_pv/l5.DAE</uri>
            </mesh>
          </geometry>
        </visual>
        <gravity>1</gravity>
        <velocity_decay/>
        <sensor name='right_hand_camera' type='camera'>
          <update_rate>10</update_rate>
          <camera name='right_hand_camera'>
            <horizontal_fov>1.09929</horizontal_fov>
            <image>
              <width>752</width>
              <height>480</height>
              <format>L8</format>
            </image>
            <clip>
              <near>0.02</near>
              <far>10</far>
            </clip>
          </camera>
          <plugin name='camera_controller' filename='libgazebo_ros_camera.so'>
            <alwaysOn>true</alwaysOn>
            <updateRate>10.0</updateRate>
            <cameraName>right_hand_camera</cameraName>
            <imageTopicName>/io/internal_camera/right_hand_camera/image_raw</imageTopicName>
            <cameraInfoTopicName>/io/internal_camera/right_hand_camera/camera_info</cameraInfoTopicName>
            <frameName>right_hand_camera</frameName>
            <focalLength>613.760435</focalLength>
            <robotNamespace>/</robotNamespace>
          </plugin>
          <pose frame=''>0.039552 -0.033 0.0695 1.5708 -0 0</pose>
        </sensor>
        <self_collide>0</self_collide>
        <kinematic>0</kinematic>
      </link>
      <joint name='right_j5' type='revolute'>
        <child>right_l5</child>
        <parent>right_l4</parent>
        <axis>
          <xyz>0 1 0</xyz>
          <limit>
            <lower>-2.9761</lower>
            <upper>2.9761</upper>
            <effort>9</effort>
            <velocity>3.485</velocity>
          </limit>
          <dynamics>
            <damping>5.5</damping>
            <friction>1.2</friction>
            <spring_reference>0</spring_reference>
            <spring_stiffness>0</spring_stiffness>
          </dynamics>
          <use_parent_model_frame>1</use_parent_model_frame>
        </axis>
        <physics>
          <provide_feedback>1</provide_feedback>
          <ode>
            <provide_feedback>1</provide_feedback>
            <implicit_spring_damper>1</implicit_spring_damper>
            <cfm_damping>1</cfm_damping>
            <limit>
              <cfm>0</cfm>
              <erp>0.2</erp>
            </limit>
          </ode>
        </physics>
      </joint>
      <link name='right_l6'>
        <pose frame=''>0.991 0.1603 0.317 1.57084 -1.39627 1.57075</pose>
        <inertial>
          <pose frame=''>0.000229 0.005118 0.029535 0 -0 0</pose>
          <mass>0.809204</mass>
          <inertia>
            <ixx>0.0110547</ixx>
            <ixy>1.86113e-06</ixy>
            <ixz>-5.00815e-06</ixz>
            <iyy>0.0109541</iyy>
            <iyz>5.53749e-05</iyz>
            <izz>0.0104905</izz>
          </inertia>
        </inertial>
        <collision name='right_l6_collision'>
          <pose frame=''>0 0.015 -0.01 0 -0 0</pose>
          <geometry>
            <cylinder>
              <length>0.05</length>
              <radius>0.055</radius>
            </cylinder>
          </geometry>
          <max_contacts>10</max_contacts>
          <surface>
            <contact>
              <ode/>
            </contact>
            <bounce/>
            <friction>
              <torsional>
                <ode/>
              </torsional>
              <ode/>
            </friction>
          </surface>
        </collision>
        <collision name='right_l6_fixed_joint_lump__right_hand_collision_1'>
          <pose frame=''>0 0 0.0445 0 -0 1.5708</pose>
          <geometry>
            <cylinder>
              <length>0.03</length>
              <radius>0.035</radius>
            </cylinder>
          </geometry>
          <max_contacts>10</max_contacts>
          <surface>
            <contact>
              <ode/>
            </contact>
            <bounce/>
            <friction>
              <torsional>
                <ode/>
              </torsional>
              <ode/>
            </friction>
          </surface>
        </collision>
        <collision name='right_l6_fixed_joint_lump__right_connector_plate_base_collision_2'>
          <pose frame=''>0 0 0.0348 0 -0 1.5708</pose>
          <geometry>
            <cylinder>
              <length>0.0302</length>
              <radius>0.04</radius>
            </cylinder>
          </geometry>
          <surface>
            <contact>
              <ode/>
            </contact>
            <friction>
              <ode/>
              <torsional>
                <ode/>
              </torsional>
            </friction>
            <bounce/>
          </surface>
          <max_contacts>10</max_contacts>
        </collision>
        <collision name='right_l6_fixed_joint_lump__right_electric_gripper_base_collision_3'>
          <pose frame=''>0 0.004 0.0639 1.5708 0 -1.5708</pose>
          <geometry>
            <cylinder>
              <length>0.1</length>
              <radius>0.029</radius>
            </cylinder>
          </geometry>
          <max_contacts>10</max_contacts>
          <surface>
            <contact>
              <ode/>
            </contact>
            <bounce/>
            <friction>
              <torsional>
                <ode/>
              </torsional>
              <ode/>
            </friction>
          </surface>
        </collision>
        <visual name='right_l6_visual'>
          <pose frame=''>0 0 0 0 -0 0</pose>
          <geometry>
            <mesh>
              <scale>1 1 1</scale>
              <uri>/home/carl/CUBoulder/robotics/workspaces/sawyer_ws/src/sawyer_robot/sawyer_description/meshes/sawyer_mp1/l6.DAE</uri>
            </mesh>
          </geometry>
        </visual>
        <visual name='right_l6_fixed_joint_lump__right_connector_plate_base_visual_1'>
          <pose frame=''>0 0 0.0213 0 -0 1.5708</pose>
          <geometry>
            <mesh>
              <scale>1 1 1</scale>
              <uri>/home/carl/CUBoulder/robotics/workspaces/sawyer_ws/src/intera_common/intera_tools_description/meshes/connector_plate/connector_plate.STL</uri>
            </mesh>
          </geometry>
          <material>
            <script>
              <name>Gazebo/FlatBlack</name>
              <uri>file://media/materials/scripts/gazebo.material</uri>
            </script>
          </material>
        </visual>
        <visual name='right_l6_fixed_joint_lump__right_electric_gripper_base_visual_2'>
          <pose frame=''>0 0 0.0389 0 -0 1.5708</pose>
          <geometry>
            <mesh>
              <scale>1 1 1</scale>
              <uri>/home/carl/CUBoulder/robotics/workspaces/sawyer_ws/src/intera_common/intera_tools_description/meshes/electric_gripper/electric_gripper_base.DAE</uri>
            </mesh>
          </geometry>
        </visual>
        <gravity>1</gravity>
        <velocity_decay/>
        <self_collide>0</self_collide>
        <kinematic>0</kinematic>
      </link>
      <joint name='right_j6' type='revolute'>
        <child>right_l6</child>
        <parent>right_l5</parent>
        <axis>
          <xyz>1 0 -7e-06</xyz>
          <limit>
            <lower>-3.14</lower>
            <upper>3.14</upper>
            <effort>9</effort>
            <velocity>4.545</velocity>
          </limit>
          <dynamics>
            <damping>1</damping>
            <friction>0.5</friction>
            <spring_reference>0</spring_reference>
            <spring_stiffness>0</spring_stiffness>
          </dynamics>
          <use_parent_model_frame>1</use_parent_model_frame>
        </axis>
        <physics>
          <provide_feedback>1</provide_feedback>
          <ode>
            <provide_feedback>1</provide_feedback>
            <implicit_spring_damper>1</implicit_spring_damper>
            <cfm_damping>1</cfm_damping>
            <limit>
              <cfm>0</cfm>
              <erp>0.2</erp>
            </limit>
          </ode>
        </physics>
      </joint>
      <link name='right_gripper_l_finger'>
        <pose frame=''>1.07542 0.157606 0.318998 -1.5708 -0.17453 -1.5708</pose>
        <inertial>
          <pose frame=''>0 0.008625 0.0375 0 -0 3.14159</pose>
          <mass>0.002</mass>
          <inertia>
            <ixx>0.020003</ixx>
            <ixy>3.07418e-20</ixy>
            <ixz>-1.3366e-19</ixz>
            <iyy>0.0200028</iyy>
            <iyz>6.46875e-07</iyz>
            <izz>0.0200001</izz>
          </inertia>
        </inertial>
        <collision name='right_gripper_l_finger_collision'>
          <pose frame=''>0 0.01725 0.04 0 -0 3.14159</pose>
          <geometry>
            <box>
              <size>0.01 0.0135 0.075</size>
            </box>
          </geometry>
          <surface>
            <contact>
              <ode>
                <kp>100000</kp>
                <kd>1</kd>
              </ode>
            </contact>
            <friction>
              <ode>
                <mu>1000</mu>
                <mu2>1000</mu2>
                <fdir1>0 0 1</fdir1>
              </ode>
              <torsional>
                <ode/>
              </torsional>
            </friction>
            <bounce/>
          </surface>
          <max_contacts>10</max_contacts>
        </collision>
        <collision name='right_gripper_l_finger_collision_1'>
          <pose frame=''>-0.005 -0.003 0.0083 0 -0 3.14159</pose>
          <geometry>
            <box>
              <size>0.01 0.05 0.017</size>
            </box>
          </geometry>
          <surface>
            <contact>
              <ode>
                <kp>100000</kp>
                <kd>1</kd>
              </ode>
            </contact>
            <friction>
              <ode>
                <mu>1000</mu>
                <mu2>1000</mu2>
                <fdir1>0 0 1</fdir1>
              </ode>
              <torsional>
                <ode/>
              </torsional>
            </friction>
            <bounce/>
          </surface>
          <max_contacts>10</max_contacts>
        </collision>
        <collision name='right_gripper_l_finger_tip_collision_2'>
          <pose frame=''>0 0.01275 0.06 0 -0 -3.14159</pose>
          <geometry>
            <box>
              <size>0.016 0.007 0.037</size>
            </box>
          </geometry>
          <surface>
            <contact>
              <ode>
                <kp>100000</kp>
                <kd>1</kd>
              </ode>
            </contact>
            <friction>
              <ode>
                <mu>1000</mu>
                <mu2>1000</mu2>
                <fdir1>0 0 1</fdir1>
              </ode>
              <torsional>
                <ode/>
              </torsional>
            </friction>
            <bounce/>
          </surface>
          <max_contacts>10</max_contacts>
        </collision>
        <visual name='right_gripper_l_finger_visual'>
          <pose frame=''>0 0 0 0 -0 3.14159</pose>
          <geometry>
            <mesh>
              <scale>1 1 1</scale>
              <uri>/home/carl/CUBoulder/robotics/workspaces/sawyer_ws/src/intera_common/intera_tools_description/meshes/electric_gripper/fingers/standard_narrow.DAE</uri>
            </mesh>
          </geometry>
          <material>
            <script>
              <uri>__default__</uri>
              <name>__default__</name>
            </script>
          </material>
        </visual>
        <visual name='right_gripper_l_finger_tip_visual_1'>
          <pose frame=''>0 0.01725 0.075 0 -0 -3.14159</pose>
          <geometry>
            <mesh>
              <scale>1 1 1</scale>
              <uri>/home/carl/CUBoulder/robotics/workspaces/sawyer_ws/src/intera_common/intera_tools_description/meshes/electric_gripper/fingers/basic_soft_tip.DAE</uri>
            </mesh>
          </geometry>
          <material>
            <script>
              <uri>__default__</uri>
              <name>__default__</name>
            </script>
          </material>
        </visual>
        <gravity>1</gravity>
        <velocity_decay/>
        <self_collide>0</self_collide>
        <kinematic>0</kinematic>
      </link>
      <joint name='right_gripper_l_finger_joint' type='prismatic'>
        <child>right_gripper_l_finger</child>
        <parent>right_l6</parent>
        <axis>
          <xyz>-7e-06 -0.173646 -0.984808</xyz>
          <limit>
            <lower>0</lower>
            <upper>0.020833</upper>
            <effort>20</effort>
            <velocity>5</velocity>
          </limit>
          <dynamics>
            <damping>100</damping>
            <friction>500</friction>
            <spring_reference>0</spring_reference>
            <spring_stiffness>0</spring_stiffness>
          </dynamics>
          <use_parent_model_frame>1</use_parent_model_frame>
        </axis>
        <physics>
          <ode>
            <implicit_spring_damper>1</implicit_spring_damper>
            <cfm_damping>1</cfm_damping>
            <limit>
              <cfm>0</cfm>
              <erp>0.2</erp>
            </limit>
          </ode>
        </physics>
      </joint>
      <link name='right_gripper_r_finger'>
        <pose frame=''>1.07542 0.157085 0.316043 -1.5708 -0.17453 -1.5708</pose>
        <inertial>
          <pose frame=''>0 -0.008625 0.0375 0 -0 0</pose>
          <mass>0.002</mass>
          <inertia>
            <ixx>0.020003</ixx>
            <ixy>0</ixy>
            <ixz>0</ixz>
            <iyy>0.0200028</iyy>
            <iyz>6.46875e-07</iyz>
            <izz>0.0200001</izz>
          </inertia>
        </inertial>
        <collision name='right_gripper_r_finger_collision'>
          <pose frame=''>0 -0.01725 0.04 0 -0 0</pose>
          <geometry>
            <box>
              <size>0.01 0.0135 0.075</size>
            </box>
          </geometry>
          <surface>
            <contact>
              <ode>
                <kp>100000</kp>
                <kd>1</kd>
              </ode>
            </contact>
            <friction>
              <ode>
                <mu>1000</mu>
                <mu2>1000</mu2>
                <fdir1>0 0 1</fdir1>
              </ode>
              <torsional>
                <ode/>
              </torsional>
            </friction>
            <bounce/>
          </surface>
          <max_contacts>10</max_contacts>
        </collision>
        <collision name='right_gripper_r_finger_collision_1'>
          <pose frame=''>0.005 0.003 0.0083 0 -0 0</pose>
          <geometry>
            <box>
              <size>0.01 0.05 0.017</size>
            </box>
          </geometry>
          <surface>
            <contact>
              <ode>
                <kp>100000</kp>
                <kd>1</kd>
              </ode>
            </contact>
            <friction>
              <ode>
                <mu>1000</mu>
                <mu2>1000</mu2>
                <fdir1>0 0 1</fdir1>
              </ode>
              <torsional>
                <ode/>
              </torsional>
            </friction>
            <bounce/>
          </surface>
          <max_contacts>10</max_contacts>
        </collision>
        <collision name='right_gripper_r_finger_tip_collision_2'>
          <pose frame=''>0 -0.01275 0.06 0 -0 0</pose>
          <geometry>
            <box>
              <size>0.016 0.007 0.037</size>
            </box>
          </geometry>
          <surface>
            <contact>
              <ode>
                <kp>100000</kp>
                <kd>1</kd>
              </ode>
            </contact>
            <friction>
              <ode>
                <mu>1000</mu>
                <mu2>1000</mu2>
                <fdir1>0 0 1</fdir1>
              </ode>
              <torsional>
                <ode/>
              </torsional>
            </friction>
            <bounce/>
          </surface>
          <max_contacts>10</max_contacts>
        </collision>
        <visual name='right_gripper_r_finger_visual'>
          <pose frame=''>0 0 0 0 -0 0</pose>
          <geometry>
            <mesh>
              <scale>1 1 1</scale>
              <uri>/home/carl/CUBoulder/robotics/workspaces/sawyer_ws/src/intera_common/intera_tools_description/meshes/electric_gripper/fingers/standard_narrow.DAE</uri>
            </mesh>
          </geometry>
          <material>
            <script>
              <uri>__default__</uri>
              <name>__default__</name>
            </script>
          </material>
        </visual>
        <visual name='right_gripper_r_finger_tip_visual_1'>
          <pose frame=''>0 -0.01725 0.075 0 -0 0</pose>
          <geometry>
            <mesh>
              <scale>1 1 1</scale>
              <uri>/home/carl/CUBoulder/robotics/workspaces/sawyer_ws/src/intera_common/intera_tools_description/meshes/electric_gripper/fingers/basic_soft_tip.DAE</uri>
            </mesh>
          </geometry>
          <material>
            <script>
              <uri>__default__</uri>
              <name>__default__</name>
            </script>
          </material>
        </visual>
        <gravity>1</gravity>
        <velocity_decay/>
        <self_collide>0</self_collide>
        <kinematic>0</kinematic>
      </link>
      <joint name='right_gripper_r_finger_joint' type='prismatic'>
        <child>right_gripper_r_finger</child>
        <parent>right_l6</parent>
        <axis>
          <xyz>-7e-06 -0.173646 -0.984808</xyz>
          <limit>
            <lower>-0.020833</lower>
            <upper>0</upper>
            <effort>20</effort>
            <velocity>5</velocity>
          </limit>
          <dynamics>
            <damping>100</damping>
            <friction>500</friction>
            <spring_reference>0</spring_reference>
            <spring_stiffness>0</spring_stiffness>
          </dynamics>
          <use_parent_model_frame>1</use_parent_model_frame>
        </axis>
        <physics>
          <ode>
            <implicit_spring_damper>1</implicit_spring_damper>
            <cfm_damping>1</cfm_damping>
            <limit>
              <cfm>0</cfm>
              <erp>0.2</erp>
            </limit>
          </ode>
        </physics>
      </joint>
      <static>0</static>
      <plugin name='sawyer_ros_control' filename='libsawyer_gazebo_ros_control.so'>
        <robotNamespace>/robot</robotNamespace>
        <robotSimType>sawyer_gazebo/SawyerRobotHWSim</robotSimType>
        <controlPeriod>0.001</controlPeriod>
        <eStopTopic>sim_estop</eStopTopic>
      </plugin>
      <pose frame=''>0 0 0.93 0 -0 0</pose>
    </model>
    <model name='green_block'>
      <link name='green_block'>
        <pose frame=''>0 0 0 0 -0 0</pose>
        <inertial>
          <pose frame=''>0.025 0.025 0.025 0 -0 0</pose>
          <mass>0.5</mass>
          <inertia>
            <ixx>0.00016875</ixx>
            <ixy>0</ixy>
            <ixz>0</ixz>
            <iyy>0.00016875</iyy>
            <iyz>0</iyz>
            <izz>0.00016875</izz>
          </inertia>
        </inertial>
        <collision name='green_block_collision'>
          <pose frame=''>0.025 0.025 0.025 0 -0 0</pose>
          <geometry>
            <box>
              <size>0.045 0.045 0.045</size>
            </box>
          </geometry>
          <surface>
            <contact>
              <ode/>
            </contact>
            <friction>
              <ode>
                <mu>1000</mu>
                <mu2>1000</mu2>
              </ode>
              <torsional>
                <ode/>
              </torsional>
            </friction>
            <bounce/>
          </surface>
          <max_contacts>10</max_contacts>
        </collision>
        <visual name='green_block_visual'>
          <pose frame=''>0.025 0.055 0.025 0 -0 0</pose>
          <geometry>
            <box>
              <size>0.045 0.045 0.045</size>
            </box>
          </geometry>
          <material>
            <script>
              <name>Gazebo/Green</name>
              <uri>file://media/materials/scripts/gazebo.material</uri>
            </script>
          </material>
        </visual>
        <gravity>1</gravity>
        <velocity_decay/>
        <self_collide>0</self_collide>
        <kinematic>0</kinematic>
      </link>
      <pose frame=''>0.4225 0.1265 0.7725 0 -0 0</pose>
    </model>
    <state world_name='default'>
      <sim_time>142 353000000</sim_time>
      <real_time>150 799740027</real_time>
      <wall_time>1521956481 408798590</wall_time>
      <iterations>142353</iterations>
      <model name='cafe_table'>
        <pose frame=''>0.75 0 0 0 -0 0</pose>
        <scale>1 1 1</scale>
        <link name='link'>
          <pose frame=''>0.75 0 0 0 -0 0</pose>
          <velocity>0 0 0 0 -0 0</velocity>
          <acceleration>0 0 0 0 -0 0</acceleration>
          <wrench>0 0 0 0 -0 0</wrench>
        </link>
      </model>
      <model name='green_block'>
        <pose frame=''>0.45725 0.122616 0.82249 -0.063113 1.57072 -0.0599</pose>
        <scale>1 1 1</scale>
        <link name='green_block'>
          <pose frame=''>0.45725 0.122616 0.82249 -0.063113 1.57072 -0.0599</pose>
          <velocity>0 0 0 0 -0 0</velocity>
          <acceleration>0 0 -9.81 0 -0 0</acceleration>
          <wrench>0 0 -4.905 0 -0 0</wrench>
        </link>
      </model>
      <model name='green_bowl_0'>
        <pose frame=''>1.22904 -0.424591 0 0 -0 0</pose>
        <scale>1 1 1</scale>
        <link name='link'>
          <pose frame=''>0.82904 -0.224591 0.78 0 -0 0</pose>
          <velocity>0 0 0 0 -0 0</velocity>
          <acceleration>0 0 0 0 -0 0</acceleration>
          <wrench>0 0 0 0 -0 0</wrench>
        </link>
      </model>
      <model name='ground_plane'>
        <pose frame=''>0 0 0 0 -0 0</pose>
        <scale>1 1 1</scale>
        <link name='link'>
          <pose frame=''>0 0 0 0 -0 0</pose>
          <velocity>0 0 0 0 -0 0</velocity>
          <acceleration>0 0 0 0 -0 0</acceleration>
          <wrench>0 0 0 0 -0 0</wrench>
        </link>
      </model>
      <model name='red_block'>
        <pose frame=''>0.59315 -0.104521 0.7725 0 0 -0.618468</pose>
        <scale>1 1 1</scale>
        <link name='red_block'>
          <pose frame=''>0.59315 -0.104521 0.7725 0 0 -0.618468</pose>
          <velocity>-0.00035 -9e-05 0.009697 -0.036141 0.140289 1e-06</velocity>
          <acceleration>6.31427 1.62647 9.18652 -0.028192 -1.01542 -3.14091</acceleration>
          <wrench>3.15714 0.813233 4.59326 0 -0 0</wrench>
        </link>
      </model>
      <model name='red_bowl'>
        <pose frame=''>1.17987 0.074057 0 0 -0 0</pose>
        <scale>1 1 1</scale>
        <link name='link'>
          <pose frame=''>0.82987 0.274057 0.78 0 -0 0</pose>
          <velocity>0 0 0 0 -0 0</velocity>
          <acceleration>0 0 0 0 -0 0</acceleration>
          <wrench>0 0 0 0 -0 0</wrench>
        </link>
      </model>
      <model name='sawyer'>
        <pose frame=''>0 0 0.93 0 -0 0</pose>
        <scale>1 1 1</scale>
        <link name='base'>
          <pose frame=''>0 0 0.93 0 -0 0</pose>
          <velocity>-2e-06 0 0 0 -3e-06 0</velocity>
          <acceleration>-0.000936 -4.5e-05 -4.1e-05 0.000857 -0.006978 -3.2e-05</acceleration>
          <wrench>-0.058962 -0.002804 -0.002592 0 -0 0</wrench>
        </link>
        <link name='head'>
          <pose frame=''>0 0 1.3065 0 0 -0.363243</pose>
          <velocity>8.1e-05 2.8e-05 -8e-06 -7.6e-05 7.8e-05 0.002483</velocity>
          <acceleration>0.176079 0.066594 -0.016034 -0.148786 0.149024 -1.1569</acceleration>
          <wrench>0.281639 0.106517 -0.025647 0 -0 0</wrench>
        </link>
        <link name='right_gripper_l_finger'>
          <pose frame=''>0.595278 -0.102516 0.877075 -3.13609 0.003477 -3.13889</pose>
          <velocity>0.003934 0.000675 0.013559 -0.002314 -0.044222 0.013364</velocity>
          <acceleration>20.5272 -3.61216 -2.03563 -1.4968 0.15334 1.39735</acceleration>
          <wrench>0.041054 -0.007224 -0.004071 0 -0 0</wrench>
        </link>
        <link name='right_gripper_r_finger'>
          <pose frame=''>0.595271 -0.099665 0.877059 -3.13609 0.003477 -3.13889</pose>
          <velocity>0.003899 0.000442 0.013554 -0.002277 -0.044251 0.013364</velocity>
          <acceleration>20.7707 -3.70695 -1.87384 -1.42112 0.208116 1.38385</acceleration>
          <wrench>0.041541 -0.007414 -0.003748 0 -0 0</wrench>
        </link>
        <link name='right_l0'>
          <pose frame=''>0 0 1.01 0 0 -0.396924</pose>
          <velocity>6e-05 2.1e-05 -1.4e-05 2.7e-05 -0.00011 0.00591</velocity>
          <acceleration>0.085677 0.181208 -0.0215 -1.94773 0.857522 -3.08331</acceleration>
          <wrench>0.456769 0.966073 -0.114622 0 -0 0</wrench>
        </link>
        <link name='right_l1'>
          <pose frame=''>0.094032 0.014799 1.247 -1.5708 1.07497 -0.396924</pose>
          <velocity>-3.8e-05 0.000571 -3e-05 -0.013671 -0.032632 0.005902</velocity>
          <acceleration>-0.410915 0.862551 -0.052612 -1.34911 -1.10692 -2.38132</acceleration>
          <wrench>-1.85528 3.89442 -0.237544 0 -0 0</wrench>
        </link>
        <link name='right_l2'>
          <pose frame=''>0.262687 0.098617 1.31361 -0.095574 1.07249 -0.505633</pose>
          <velocity>-0.002669 0.00251 0.004326 -0.020276 -0.029885 0.00225</velocity>
          <acceleration>-0.11481 2.21529 0.136019 1.92422 0.499336 1.35036</acceleration>
          <wrench>-0.201491 3.88783 0.238714 0 -0 0</wrench>
        </link>
        <link name='right_l3'>
          <pose frame=''>0.456426 -0.028073 1.43922 1.61965 0.365763 2.73746</pose>
          <velocity>-0.006053 0.00548 0.012729 0.002457 0.020693 -0.000352</velocity>
          <acceleration>-1.20913 3.26579 0.187846 -0.656143 0.220605 -2.20261</acceleration>
          <wrench>-3.03454 8.19615 0.471437 0 -0 0</wrench>
        </link>
        <link name='right_l4'>
          <pose frame=''>0.443368 -0.166547 1.3284 -3.13842 0.368853 2.61038</pose>
          <velocity>-0.008376 0.005756 0.012668 0.027765 0.005536 -0.076647</velocity>
          <acceleration>-14.7652 6.66831 -4.56863 2.64446 0.516479 0.042248</acceleration>
          <wrench>-16.7379 7.5592 -5.179 0 -0 0</wrench>
        </link>
        <link name='right_l5'>
          <pose frame=''>0.544148 -0.190817 1.07181 1.57375 0.005803 2.60926</pose>
          <velocity>-0.011656 0.00516 0.011435 -0.001907 -0.044791 -0.076481</velocity>
          <acceleration>-5.91629 1.87295 -3.72557 0.128497 -0.622918 -3.05285</acceleration>
          <wrench>-9.36254 2.96394 -5.89571 0 -0 0</wrench>
        </link>
        <link name='right_l6'>
          <pose frame=''>0.59798 -0.100694 0.961496 -3.13811 -0.005502 -1.56812</pose>
          <velocity>0.000176 0.00083 0.013675 -0.002241 -0.044279 0.013365</velocity>
          <acceleration>10.4728 -2.78646 -2.22558 -0.611023 -0.518383 0.804673</acceleration>
          <wrench>8.4746 -2.25481 -1.80095 0 -0 0</wrench>
        </link>
      </model>
      <light name='sun'>
        <pose frame=''>0 0 10 0 -0 0</pose>
      </light>
    </state>
    <model name='red_bowl'>
      <link name='link'>
        <pose frame=''>-0.35 0.2 0.78 0 -0 0</pose>
        <inertial>
          <pose frame=''>0 0 0.25 0 -0 0</pose>
          <mass>0.1</mass>
          <inertia>
            <ixx>0.00025031</ixx>
            <ixy>0</ixy>
            <ixz>0</ixz>
            <iyy>0.00025031</iyy>
            <iyz>0</iyz>
            <izz>0.0004802</izz>
          </inertia>
        </inertial>
        <self_collide>0</self_collide>
        <kinematic>1</kinematic>
        <gravity>1</gravity>
        <visual name='visual'>
          <geometry>
            <mesh>
              <uri>model://bowl/meshes/bowl.dae</uri>
            </mesh>
          </geometry>
          <pose frame=''>0 0 0 0 -0 0</pose>
          <cast_shadows>1</cast_shadows>
          <transparency>0</transparency>
          <material>
            <ambient>1 0 0 1</ambient>
            <diffuse>1 1 1 1</diffuse>
            <specular>0 0 0 1</specular>
            <emissive>0 0 0 1</emissive>
            <script>
              <name>ModelPreview_3::link::visual_MATERIAL_</name>
              <uri>__default__</uri>
            </script>
            <shader type='vertex'>
              <normal_map>__default__</normal_map>
            </shader>
          </material>
        </visual>
        <collision name='collision'>
          <laser_retro>0</laser_retro>
          <max_contacts>10</max_contacts>
          <pose frame=''>0 0 0.0175 0 -0 0</pose>
          <geometry>
            <cylinder>
              <radius>0.098</radius>
              <length>0.035</length>
            </cylinder>
          </geometry>
          <surface>
            <friction>
              <ode>
                <mu>1</mu>
                <mu2>1</mu2>
                <fdir1>0 0 0</fdir1>
                <slip1>0</slip1>
                <slip2>0</slip2>
              </ode>
              <torsional>
                <coefficient>1</coefficient>
                <patch_radius>0</patch_radius>
                <surface_radius>0</surface_radius>
                <use_patch_radius>1</use_patch_radius>
                <ode>
                  <slip>0</slip>
                </ode>
              </torsional>
            </friction>
            <bounce>
              <restitution_coefficient>0</restitution_coefficient>
              <threshold>1e+06</threshold>
            </bounce>
            <contact>
              <collide_without_contact>0</collide_without_contact>
              <collide_without_contact_bitmask>1</collide_without_contact_bitmask>
              <collide_bitmask>1</collide_bitmask>
              <ode>
                <soft_cfm>0</soft_cfm>
                <soft_erp>0.2</soft_erp>
                <kp>1e+13</kp>
                <kd>1</kd>
                <max_vel>0.01</max_vel>
                <min_depth>0</min_depth>
              </ode>
              <bullet>
                <split_impulse>1</split_impulse>
                <split_impulse_penetration_threshold>-0.01</split_impulse_penetration_threshold>
                <soft_cfm>0</soft_cfm>
                <soft_erp>0.2</soft_erp>
                <kp>1e+13</kp>
                <kd>1</kd>
              </bullet>
            </contact>
          </surface>
        </collision>
      </link>
      <static>0</static>
      <allow_auto_disable>1</allow_auto_disable>
      <pose frame=''>1.17987 0.074057 0 0 -0 0</pose>
    </model>
    <model name='green_bowl_0'>
      <link name='link'>
        <pose frame=''>-0.4 0.2 0.78 0 -0 0</pose>
        <inertial>
          <pose frame=''>0 0 0.25 0 -0 0</pose>
          <mass>0.1</mass>
          <inertia>
            <ixx>0.00025031</ixx>
            <ixy>0</ixy>
            <ixz>0</ixz>
            <iyy>0.00025031</iyy>
            <iyz>0</iyz>
            <izz>0.0004802</izz>
          </inertia>
        </inertial>
        <self_collide>0</self_collide>
        <kinematic>1</kinematic>
        <gravity>1</gravity>
        <visual name='visual'>
          <geometry>
            <mesh>
              <uri>model://bowl/meshes/bowl.dae</uri>
            </mesh>
          </geometry>
          <pose frame=''>0 0 0 0 -0 0</pose>
          <cast_shadows>1</cast_shadows>
          <transparency>0</transparency>
          <material>
            <ambient>0 1 0 1</ambient>
            <diffuse>1 1 1 1</diffuse>
            <specular>0 0 0 1</specular>
            <emissive>0 0 0 1</emissive>
            <script>
              <name>ModelPreview_3::link::visual_MATERIAL_</name>
              <uri>__default__</uri>
            </script>
            <shader type='vertex'>
              <normal_map>__default__</normal_map>
            </shader>
          </material>
        </visual>
        <collision name='collision'>
          <laser_retro>0</laser_retro>
          <max_contacts>10</max_contacts>
          <pose frame=''>0 0 0.0175 0 -0 0</pose>
          <geometry>
            <cylinder>
              <radius>0.098</radius>
              <length>0.035</length>
            </cylinder>
          </geometry>
          <surface>
            <friction>
              <ode>
                <mu>1</mu>
                <mu2>1</mu2>
                <fdir1>0 0 0</fdir1>
                <slip1>0</slip1>
                <slip2>0</slip2>
              </ode>
              <torsional>
                <coefficient>1</coefficient>
                <patch_radius>0</patch_radius>
                <surface_radius>0</surface_radius>
                <use_patch_radius>1</use_patch_radius>
                <ode>
                  <slip>0</slip>
                </ode>
              </torsional>
            </friction>
            <bounce>
              <restitution_coefficient>0</restitution_coefficient>
              <threshold>1e+06</threshold>
            </bounce>
            <contact>
              <collide_without_contact>0</collide_without_contact>
              <collide_without_contact_bitmask>1</collide_without_contact_bitmask>
              <collide_bitmask>1</collide_bitmask>
              <ode>
                <soft_cfm>0</soft_cfm>
                <soft_erp>0.2</soft_erp>
                <kp>1e+13</kp>
                <kd>1</kd>
                <max_vel>0.01</max_vel>
                <min_depth>0</min_depth>
              </ode>
              <bullet>
                <split_impulse>1</split_impulse>
                <split_impulse_penetration_threshold>-0.01</split_impulse_penetration_threshold>
                <soft_cfm>0</soft_cfm>
                <soft_erp>0.2</soft_erp>
                <kp>1e+13</kp>
                <kd>1</kd>
              </bullet>
            </contact>
          </surface>
        </collision>
      </link>
      <static>0</static>
      <allow_auto_disable>1</allow_auto_disable>
      <pose frame=''>1.22904 -0.424591 0 0 -0 0</pose>
    </model>
  </world>
</sdf>
